{
  "project": "7793e2058c5c9dacb5212c0ac0b18a8a",
  "attempts": [
    {
      "attempt": 1,
      "timestamp": "2025-10-28T12:13:55Z",
      "image_tag": "7793e2058c5c9dacb5212c0ac0b18a8a_trial_1_1edf94ee",
      "build": {
        "returncode": 0,
        "stdout_tail": "",
        "stderr_tail": "",
        "time_sec": 5.35
      },
      "run": {
        "returncode": 1,
        "stdout_tail": "",
        "stderr_tail": "Traceback (most recent call last):\n  File \"/app/snippet.py\", line 8, in <module>\n    from keras import backend as K\n  File \"/usr/local/lib/python3.9/site-packages/keras/__init__.py\", line 3, in <module>\n    from keras import __internal__\n  File \"/usr/local/lib/python3.9/site-packages/keras/__internal__/__init__.py\", line 3, in <module>\n    from keras.__internal__ import backend\n  File \"/usr/local/lib/python3.9/site-packages/keras/__internal__/backend/__init__.py\", line 3, in <module>\n    from keras.src.backend import _initialize_variables as initialize_variables\n  File \"/usr/local/lib/python3.9/site-packages/keras/src/__init__.py\", line 21, in <module>\n    from keras.src import applications\n  File \"/usr/local/lib/python3.9/site-packages/keras/src/applications/__init__.py\", line 18, in <module>\n    from keras.src.applications.convnext import ConvNeXtBase\n  File \"/usr/local/lib/python3.9/site-packages/keras/src/applications/convnext.py\", line 25, in <module>\n    import numpy as np\nModuleNotFoundError: No module named 'numpy'\n",
        "time_sec": 1.25
      },
      "applied_agent": "dependency",
      "applied_fixes": {
        "requirements": [
          "numpy>=1.2.0"
        ],
        "rationale": [
          "The error message suggests that the NumPy library is not installed or cannot be imported. Adding this requirement line should fix the issue."
        ],
        "meta": {
          "chosen_candidate": 1,
          "chosen_confidence": 0.9,
          "notes": [
            "The error message suggests that the NumPy library is not installed or cannot be imported. Adding this requirement line should fix the issue."
          ]
        }
      }
    },
    {
      "attempt": 2,
      "timestamp": "2025-10-28T12:14:10Z",
      "image_tag": "7793e2058c5c9dacb5212c0ac0b18a8a_trial_2_f3b3bfbe",
      "build": {
        "returncode": 0,
        "stdout_tail": "",
        "stderr_tail": " FROM docker.io/library/python:3.9-slim@sha256:545badebace9a958b98d3e272f0f0d46c0a1a389ac77e24c33f2e7b548ce1b6b\n#6 resolve docker.io/library/python:3.9-slim@sha256:545badebace9a958b98d3e272f0f0d46c0a1a389ac77e24c33f2e7b548ce1b6b 0.1s done\n#6 DONE 0.1s\n\n#5 [internal] load build context\n#5 transferring context: 1.44kB done\n#5 DONE 0.0s\n\n#7 [4/5] COPY requirements.txt /app/requirements.txt\n#7 CACHED\n\n#8 [2/5] WORKDIR /app\n#8 CACHED\n\n#9 [3/5] COPY snippet.py /app/snippet.py\n#9 CACHED\n\n#10 [5/5] RUN if [ -s /app/requirements.txt ]; then pip install --no-cache-dir -r /app/requirements.txt; fi\n#10 CACHED\n\n#11 exporting to image\n#11 exporting layers done\n#11 exporting manifest sha256:2b7c901013edab809966eaecea1e7c792a3faf3df206656e3203ef1da1108d2f 0.0s done\n#11 exporting config sha256:63906e321cd08c2e6ac3e48f325324341150ca10e076166af3be8b54fa8a557f 0.0s done\n#11 exporting attestation manifest sha256:933367c123f2f3c9c673d2b4c99cf595d75e718c96117cd46bc31aa8aab2dd74 0.1s done\n#11 exporting manifest list sha256:4e8350cc4ed13a116597ac5b5f5fcfda1ea227454ae63916924479cfbfaa5871\n#11 exporting manifest list sha256:4e8350cc4ed13a116597ac5b5f5fcfda1ea227454ae63916924479cfbfaa5871 0.0s done\n#11 naming to docker.io/library/7793e2058c5c9dacb5212c0ac0b18a8a_trial_2_f3b3bfbe:latest done\n#11 unpacking to docker.io/library/7793e2058c5c9dacb5212c0ac0b18a8a_trial_2_f3b3bfbe:latest\n#11 unpacking to docker.io/library/7793e2058c5c9dacb5212c0ac0b18a8a_trial_2_f3b3bfbe:latest 0.5s done\n#11 DONE 0.7s\n\nView build details: docker-desktop://dashboard/build/desktop-linux/desktop-linux/f66n14l2q83cknmbv0bjqelk5\n",
        "time_sec": 1.9
      },
      "run": {
        "returncode": 1,
        "stdout_tail": "",
        "stderr_tail": "Traceback (most recent call last):\n  File \"/app/snippet.py\", line 8, in <module>\n    from keras import backend as K\n  File \"/usr/local/lib/python3.9/site-packages/keras/__init__.py\", line 3, in <module>\n    from keras import __internal__\n  File \"/usr/local/lib/python3.9/site-packages/keras/__internal__/__init__.py\", line 3, in <module>\n    from keras.__internal__ import backend\n  File \"/usr/local/lib/python3.9/site-packages/keras/__internal__/backend/__init__.py\", line 3, in <module>\n    from keras.src.backend import _initialize_variables as initialize_variables\n  File \"/usr/local/lib/python3.9/site-packages/keras/src/__init__.py\", line 21, in <module>\n    from keras.src import applications\n  File \"/usr/local/lib/python3.9/site-packages/keras/src/applications/__init__.py\", line 18, in <module>\n    from keras.src.applications.convnext import ConvNeXtBase\n  File \"/usr/local/lib/python3.9/site-packages/keras/src/applications/convnext.py\", line 25, in <module>\n    import numpy as np\nModuleNotFoundError: No module named 'numpy'\n",
        "time_sec": 1.26
      },
      "applied_agent": "dependency",
      "applied_fixes": null
    }
  ],
  "final_status": "failed_no_fixes",
  "total_time_sec": 29.18,
  "metrics": {
    "total_attempts": 2,
    "success_attempt": null,
    "attempts_to_success": null,
    "total_time_sec": 29.18,
    "avg_build_time_sec": 3.62,
    "avg_run_time_sec": 1.25,
    "avg_chosen_confidence": 0.0,
    "fix_type_counts": {
      "dependency": 2
    }
  }
}